---
title: Python异常处理的那些事
date: 2022-03-26 20:00:00
permalink: /sec/dev/python/exception
author:
 name: p0jo
 link: https://wiki.pwddd.com
categories:
  - 安全开发
  - Python
tags:
  - Python
---


# Python异常机制的那些事

> 异常是程序在运行过程中，由于用户输入或者其他原因导致的程序中出现的非正常的运行现象。异常处理是指程序在出现问题时依然可以正确的执行代码，不会因为异常而终止程序运行。

<!-- more -->

Python中引进了很多用来描述和处理异常的类，称为异常类，异常类定义中包含了该异常的信息和处理的方法。

针对异常的处理态度包含两个方式：

- 抛出异常：在执行一个方法时，如果发生异常，则这个方法生成代表该异常的一个对象，停止执行当前的执行路径，并把异常对象提交给解释器。
- 捕获异常：解释器获得到异常之后，寻找相关的代码处理异常。





## Python异常处理

### try...except结构

try...except是最常见的异常处理机制，和Java中的try...catch类似。结构如下：

```python
try:
    a = 1/0
except BaseException as e:
    print(e) # division by zero
```

try块包含着可能引发异常的代码，except块用于捕获和处理发生的异常。执行的时候，如果try中没有引发异常，则不会执行except中的代码，如果引发了异常，则会跳过异常后的语句，执行except中的异常处理代码，处理完成之后，继续运行try...except后续代码。

同时，如果一个try中可能出现多个类型的异常，就可以添加多个Exception的except。如下所示：

```python
try:
    a = input("请输入被除数：")
    b = input("请输入除数：")
    c = float(a)/float(b)
    print(c)
except ZeroDivisionError:
    print("除数不能为0")
except TypeError:
    print("除数和被除数应该为数")
except NameError:
    print("变量不存在")
except BaseException as e:
    print(e)
    print(type(e))
```

try...except...else结构中增加了一个else快，如果try中没有抛出异常，则执行else块，如果执行了except块，就不执行了else块。

```python
try:
    a = input("请输入被除数：")
    b = input("请输入除数：")
    c = float(a)/float(b)
    print(c)
except ZeroDivisionError:
    print("除数不能为0")
except TypeError:
    print("除数和被除数应该为数")
except NameError:
    print("变量不存在")
except BaseException as e:
    print(e)
    print(type(e))
else:
    print("aaa")
```

Try...except...finally结构中，无论是否发生异常都会执行finally中的语句，通常用finally中的语句用来释放资源。

```python
try:
    a = input("hello")
    b = input("world")
    c = float(a)/float(b)
    print(c)
except BaseException as e:
    print(e)
else:
    print(c)
finally:
    print("hahhahaha")
print("end")
```



### return语句和异常处理

return语句有两种作用，结束方法运行和返回值。我们一般不会把return语句放到异常处理的结构中，通常放到方法最后。



## 常见异常汇总

| 异常名称                  | 说明                                               |
| ------------------------- | -------------------------------------------------- |
| ArithmeticError           | 所有数值计算错误的基类                             |
| AssertionError            | 断言语句失败                                       |
| AttributeError            | 对象没有这个属性                                   |
| BaseException             | 所有异常的基类                                     |
| DeprecationWarning        | 关于被弃用的特征的警告                             |
| EnvironmentError          | 操作系统错误的基类                                 |
| EOFError                  | 没有内建输入,到达 EOF 标记                         |
| Exception                 | 常规错误的基类                                     |
| FloatingPointError        | 浮点计算错误                                       |
| FutureWarning             | 关于构造将来语义会有改变的警告                     |
| GeneratorExit             | 生成器(generator)发生异常来通知退出                |
| ImportError               | 导入模块/对象失败                                  |
| IndentationError          | 缩进错误                                           |
| IndexError                | 序列中没有此索引(index)                            |
| IOError                   | 输入/输出操作失败                                  |
| KeyboardInterrupt         | 用户中断执行(通常是输入^C)                         |
| KeyError                  | 映射中没有这个键                                   |
| LookupError               | 无效数据查询的基类                                 |
| MemoryError               | 内存溢出错误(对于 Python 解释器不是致命的)         |
| NameError                 | 未声明/初始化对象 (没有属性)                       |
| NotImplementedError       | 尚未实现的方法                                     |
| OSError                   | 操作系统错误                                       |
| OverflowError             | 数值运算超出最大限制                               |
| OverflowWarning           | 旧的关于自动提升为长整型(long)的警告               |
| PendingDeprecationWarning | 关于特性将会被废弃的警告                           |
| ReferenceError            | 弱引用(Weak reference)试图访问已经垃圾回收了的对象 |
| RuntimeError              | 一般的运行时错误                                   |
| RuntimeWarning            | 可疑的运行时行为(runtime behavior)的警告           |
| StandardError             | 所有的内建标准异常的基类                           |
| StopIteration             | 迭代器没有更多的值                                 |
| SyntaxError               | Python 语法错误                                    |
| SyntaxWarning             | 可疑的语法的警告                                   |
| SystemError               | 一般的解释器系统错误                               |
| SystemExit                | 解释器请求退出                                     |
| TabError                  | Tab 和空格混用                                     |
| TypeError                 | 对类型无效的操作                                   |
| UnboundLocalError         | 访问未初始化的本地变量                             |
| UnicodeDecodeError        | Unicode 解码时的错误                               |
| UnicodeEncodeError        | Unicode 编码时错误                                 |
| UnicodeError              | Unicode 相关的错误                                 |
| UnicodeTranslateError     | Unicode 转换时错误                                 |
| UserWarning               | 用户代码生成的警告                                 |
| ValueError                | 传入无效的参数                                     |
| Warning                   | 警告的基类                                         |
| WindowsError              | 系统调用失败                                       |
| ZeroDivisionError         | 除(或取模)零 (所有数据类型)                        |



## with上下文管理

finally块由于在是否发生异常都会执行，通常用来释放资源代码，我们也可以通过with进行上下文的管理，更方便实现资源的释放。

with上下文管理可以自动的管理资源，在with代码块执行完成之后，自动还原进入代码之前的上下文，不管是因为什么原因跳出了with，总能保证资源的及时释放。

with的使用方法如下所示：

```python
with open("d:/aaa.txt") as f:
  for line in f:
    print(line)
```

## trackback模块

使用traceback模块可以打印异常的信息。

```python
import traceback
try:
    print(1/0)
except:
    traceback.print_exc()
"""
Traceback (most recent call last):
  File "/Users/plankton/Workspace/Py/StudyPy/demo.py", line 942, in <module>
    print(1/0)
ZeroDivisionError: division by zero
"""

try:
    print("hello")
    a = 1/0
except:
    with open("./error.log","a") as f:
        traceback.print_exc(file=f)
```



## 自定义异常类

在程序开发中，我们有时候需要自定义异常的类，通常继承Exception即可，命名为Error、Exception等。下面是一个异常类的例子：

```python
class MyException(Exception):
    def __init__(self,errorInfo):
        Exception.__init__(self)
        self.errorInfo = errorInfo
    def __str__(self):
        return str(self.errorInfo)+"hahaha"

if __name__ == '__main__':
    age = int(input("aaa"))
    if age <1 or age>100:
        raise MyException("报错了")
    else:
        print("age",age)
        
        """
        aaa123
Traceback (most recent call last):
  File "/Users/plankton/Workspace/Py/StudyPy/demo.py", line 970, in <module>
    raise MyException("报错了")
__main__.MyException: 报错了hahaha
        """
```

在程序中抛出异常可以使用raise